<?xml version="1.0" ?>
<!-- =================================================================================== -->
<!-- |    This document was autogenerated by xacro from ndt2_witharm.xacro             | -->
<!-- |    EDITING THIS FILE BY HAND IS NOT RECOMMENDED                                 | -->
<!-- =================================================================================== -->
<!--

	Copyright 2021 Jonathan Cacace, Fabio Pierro, Salvatore Marcellini, Prisma LAB, Naples, Italy

  Licensed under the Apache License, Version 2.0 (the "License");
  you may not use this file except in compliance with the License.
  You may obtain a copy of the License at

  http://www.apache.org/licenses/LICENSE-2.0

  Unless required by applicable law or agreed to in writing, software
  distributed under the License is distributed on an "AS IS" BASIS,
  WITHOUT WARRANTIES OR CONDITIONS OF ANY KIND, either express or implied.
  See the License for the specific language governing permissions and
  limitations under the License.
-->
<robot name="ndt2">
  <transmission name="tilt_motor_2_tran">
    <type>transmission_interface/SimpleTransmission</type>
    <joint name="tilt_motor_2">
      <hardwareInterface>hardware_interface/PositionJointInterface</hardwareInterface>
    </joint>
    <actuator name="tilt_motor_2_actr">
      <hardwareInterface>hardware_interface/PositionJointInterface</hardwareInterface>
      <mechanicalReduction>1</mechanicalReduction>
    </actuator>
  </transmission>
  <transmission name="tilt_motor_3_tran">
    <type>transmission_interface/SimpleTransmission</type>
    <joint name="tilt_motor_3">
      <hardwareInterface>hardware_interface/PositionJointInterface</hardwareInterface>
    </joint>
    <actuator name="tilt_motor_3_actr">
      <hardwareInterface>hardware_interface/PositionJointInterface</hardwareInterface>
      <mechanicalReduction>1</mechanicalReduction>
    </actuator>
  </transmission>
  <transmission name="tilt_motor_4_tran">
    <type>transmission_interface/SimpleTransmission</type>
    <joint name="tilt_motor_4">
      <hardwareInterface>hardware_interface/PositionJointInterface</hardwareInterface>
    </joint>
    <actuator name="tilt_motor_4_actr">
      <hardwareInterface>hardware_interface/PositionJointInterface</hardwareInterface>
      <mechanicalReduction>1</mechanicalReduction>
    </actuator>
  </transmission>
  <transmission name="tilt_motor_1_tran">
    <type>transmission_interface/SimpleTransmission</type>
    <joint name="tilt_motor_1">
      <hardwareInterface>hardware_interface/PositionJointInterface</hardwareInterface>
    </joint>
    <actuator name="tilt_motor_1_actr">
      <hardwareInterface>hardware_interface/PositionJointInterface</hardwareInterface>
      <mechanicalReduction>1</mechanicalReduction>
    </actuator>
  </transmission>
  <gazebo reference="base_link">
    <material>DarkGrey</material>
    <!--
    <mu1>0.2</mu1>
    <mu2>0.2</mu2>
    -->
    <selfCollide>true</selfCollide>
    <gravity>true</gravity>
  </gazebo>
  <gazebo reference="arm_4">
    <material>DarkGrey</material>
    <mu1>0.2</mu1>
    <mu2>0.2</mu2>
    <selfCollide>true</selfCollide>
  </gazebo>
  <gazebo reference="arm_2">
    <material>DarkGrey</material>
    <mu1>0.2</mu1>
    <mu2>0.2</mu2>
    <selfCollide>true</selfCollide>
  </gazebo>
  <gazebo reference="arm_3">
    <material>DarkGrey</material>
    <mu1>0.2</mu1>
    <mu2>0.2</mu2>
    <selfCollide>true</selfCollide>
  </gazebo>
  <gazebo reference="arm_1">
    <material>DarkGrey</material>
    <mu1>0.2</mu1>
    <mu2>0.2</mu2>
    <selfCollide>true</selfCollide>
  </gazebo>
  <link name="base_link"/>
  <joint name="base_joint" type="fixed">
    <origin rpy="0 0 0" xyz="0 0 0"/>
    <parent link="base_link"/>
    <child link="base_link_inertia"/>
  </joint>
  <link name="base_link_inertia">
    <inertial>
      <mass value="5"/>
      <!-- [kg] -->
      <origin xyz="0 0 0"/>
      <inertia ixx="0.1522083333333333" ixy="0.0" ixz="0.0" iyy="0.1522083333333333" iyz="0.0" izz="0.1840833333333333"/>
    </inertial>
    <visual>
      <origin rpy="0 0 0" xyz="0 0 0"/>
      <geometry>
        <mesh filename="package://mav_description/meshes/ndt2/chassis_res.stl" scale="1 1 1"/>
        <!-- <box size="${body_width} ${body_width} ${body_height}"/> -->
        <!-- [m] [m] [m] -->
      </geometry>
    </visual>
    <collision>
      <origin rpy="0 0 0" xyz="0 0 0"/>
      <geometry>
        <mesh filename="package://mav_description/meshes/ndt2/chassis_res.stl" scale="1 1 1"/>
      </geometry>
    </collision>
  </link>
  <!-- attach multirotor_base_plugin to the base_link -->
  <gazebo>
    <plugin filename="librotors_gazebo_multirotor_base_plugin.so" name="rosbag">
      <robotNamespace>ndt2</robotNamespace>
      <linkName>base_link</linkName>
      <rotorVelocitySlowdownSim>100</rotorVelocitySlowdownSim>
    </plugin>
  </gazebo>
  <gazebo reference="base_link">
    <material>Gazebo/Gray</material>
    <collision name="base_link_inertia_collision">
      <surface>
        <contact>
          <ode>
            <min_depth>0.001</min_depth>
            <max_vel>0.0</max_vel>
          </ode>
        </contact>
        <friction>
          <ode/>
        </friction>
      </surface>
    </collision>
  </gazebo>
  <link name="arm_4">
    <inertial>
      <origin rpy="0 0 0" xyz="0.083 -0.083 0"/>
      <mass value="0.1"/>
      <inertia ixx="0.0009933333333333335" ixy="0.0" ixz="0.0" iyy="0.0009933333333333335" iyz="0.0" izz="0.001926666666666667"/>
    </inertial>
    <visual>
      <!--
      <origin rpy="0 0 3.1415" xyz="-0.16832475 0.175539 -0.02"/>
      -->
      <origin rpy="0 0 3.1415" xyz="0.0 0.0 -0.02"/>
      <geometry>
        <mesh filename="/home/simone/uav_ws/src/mav_description/meshes/ndt2/arm_4.stl"/>
      </geometry>
    </visual>
    <collision>
      <origin rpy="0 0 3.1415" xyz="0.0 0.0 -0.02"/>
      <geometry>
        <mesh filename="/home/simone/uav_ws/src/mav_description/meshes/ndt2/arm_4.stl"/>
      </geometry>
    </collision>
  </link>
  <joint name="tilt_motor_4" type="revolute">
    <!--<origin rpy="0 0 3.1415" xyz="0.16832475 -0.175539 0.04"/>-->
    <origin rpy="0 0 3.1415" xyz="0.0 0.0 0.02"/>
    <parent link="base_link"/>
    <child link="arm_4"/>
    <axis xyz="-0.707107 0.707107 0.0"/>
    <limit effort="30" lower="-1.57" upper="1.57" velocity="1.0"/>
  </joint>
  <link name="arm_2">
    <inertial>
      <origin rpy="0 0 0" xyz="-0.083 0.083 0"/>
      <mass value="0.1"/>
      <inertia ixx="0.0009933333333333335" ixy="0.0" ixz="0.0" iyy="0.0009933333333333335" iyz="0.0" izz="0.001926666666666667"/>
    </inertial>
    <visual>
      <!--<origin rpy="0 0 0" xyz="0.224433 -0.234052 -0.04"/>-->
      <origin rpy="0 0 0" xyz="0.0 -0.0 -0.02"/>
      <geometry>
        <mesh filename="/home/simone/uav_ws/src/mav_description/meshes/ndt2/arm_2.stl"/>
      </geometry>
    </visual>
    <collision>
      <origin rpy="0 0 0" xyz="0.0 -0.0 -0.02"/>
      <geometry>
        <mesh filename="/home/simone/uav_ws/src/mav_description/meshes/ndt2/arm_2.stl"/>
      </geometry>
    </collision>
  </link>
  <joint name="tilt_motor_2" type="revolute">
    <!--<origin rpy="0 0 0" xyz="-0.224433 0.234052 0.04"/>-->
    <origin rpy="0 0 0" xyz="-0.0 0.0 0.02"/>
    <parent link="base_link"/>
    <child link="arm_2"/>
    <axis xyz="-0.707107 0.707107 0.0"/>
    <limit effort="30" lower="-1.57" upper="1.57" velocity="1.0"/>
  </joint>
  <link name="arm_3">
    <inertial>
      <origin rpy="0 0 0" xyz="-0.083 -0.083 0"/>
      <mass value="0.1"/>
      <inertia ixx="0.0009933333333333335" ixy="0.0" ixz="0.0" iyy="0.0009933333333333335" iyz="0.0" izz="0.001926666666666667"/>
    </inertial>
    <visual>
      <origin rpy="0 0 3.1415" xyz="0.0 0.0 -0.02"/>
      <geometry>
        <mesh filename="/home/simone/uav_ws/src/mav_description/meshes/ndt2/arm_3.stl"/>
      </geometry>
    </visual>
    <collision>
      <origin rpy="0 0 3.1415" xyz="0.0 0.0 -0.02"/>
      <geometry>
        <mesh filename="/home/simone/uav_ws/src/mav_description/meshes/ndt2/arm_3.stl"/>
      </geometry>
    </collision>
  </link>
  <joint name="tilt_motor_3" type="revolute">
    <origin rpy="0 0 3.1415" xyz="0.0 0.0 0.02"/>
    <parent link="base_link"/>
    <child link="arm_3"/>
    <axis xyz="0.707107 0.707107 0.0"/>
    <limit effort="30" lower="-1.57" upper="1.57" velocity="1.0"/>
  </joint>
  <link name="arm_1">
    <inertial>
      <origin rpy="0 0 0" xyz="0.083 0.083 0"/>
      <mass value="0.1"/>
      <inertia ixx="0.0009933333333333335" ixy="0.0" ixz="0.0" iyy="0.0009933333333333335" iyz="0.0" izz="0.001926666666666667"/>
    </inertial>
    <visual>
      <origin rpy="0 0 3.1415" xyz="0.0 0.0 -0.02"/>
      <geometry>
        <mesh filename="/home/simone/uav_ws/src/mav_description/meshes/ndt2/arm_1.stl"/>
      </geometry>
    </visual>
    <collision>
      <origin rpy="0 0 3.1415" xyz="0.0 0.0 -0.02"/>
      <geometry>
        <mesh filename="/home/simone/uav_ws/src/mav_description/meshes/ndt2/arm_1.stl"/>
      </geometry>
    </collision>
  </link>
  <joint name="tilt_motor_1" type="revolute">
    <origin rpy="0 0 3.1415" xyz="0.0 0.0 0.02"/>
    <parent link="base_link"/>
    <child link="arm_1"/>
    <axis xyz="-0.707107 -0.707107 0.0"/>
    <limit effort="30" lower="-1.57" upper="1.57" velocity="1.0"/>
  </joint>
  <joint name="rotor_0_joint" type="continuous">
    <origin rpy="0 0 0" xyz="-0.175 0.175 0.035"/>
    <axis xyz="0 0 1"/>
    <!-- TODO(ff): not currently set because it's not yet supported -->
    <!-- <limit effort="2000" velocity="${max_rot_velocity}" /> -->
    <parent link="arm_4"/>
    <child link="rotor_0"/>
  </joint>
  <!-- TODO(ff): not currently set because it's not yet supported -->
  <!-- <gazebo reference="rotor_${motor_number}_joint"> <axis> <xyz>0 0 1</xyz>
      <limit> <velocity> ${max_rot_velocity} </velocity> </limit> </axis> </gazebo> -->
  <link name="rotor_0">
    <inertial>
      <mass value="0.001"/>
      <!-- [kg] -->
      <inertia ixx="1.95e-06" ixy="0.0" ixz="0.0" iyy="0.0005462083333333332" iyz="0.0" izz="0.0005480083333333334"/>
    </inertial>
    <visual>
      <geometry>
        <!-- <cylinder length="0.005" radius="${radius_rotor}"/> -->
        <!-- [m] -->
        <!-- <mesh filename="package://mav_description/meshes/propeller_${direction}.dae" -->
        <mesh filename="package://mav_description/meshes/ndt2/prop.stl_ccw.dae" scale="1 1 1"/>
        <!-- <box size="${2*radius_rotor} 0.01 0.005"/> -->
      </geometry>
    </visual>
    <collision>
      <geometry>
        <cylinder length="0.005" radius="0.128"/>
        <!-- [m] -->
      </geometry>
    </collision>
  </link>
  <gazebo>
    <plugin filename="librotors_gazebo_motor_model.so" name="front_right_motor_model">
      <robotNamespace>ndt2</robotNamespace>
      <jointName>rotor_0_joint</jointName>
      <linkName>rotor_0</linkName>
      <turningDirection>ccw</turningDirection>
      <timeConstantUp>0.0125</timeConstantUp>
      <timeConstantDown>0.025</timeConstantDown>
      <maxRotVelocity>1100</maxRotVelocity>
      <motorConstant>8.54858e-05</motorConstant>
      <momentConstant>0.06</momentConstant>
      <commandSubTopic>/gazebo/command/motor_speed</commandSubTopic>
      <motorNumber>0</motorNumber>
      <rotorDragCoefficient>0.000175</rotorDragCoefficient>
      <rollingMomentCoefficient>1e-06</rollingMomentCoefficient>
      <motorSpeedPubTopic>/motor_speed/0</motorSpeedPubTopic>
      <rotorVelocitySlowdownSim>100</rotorVelocitySlowdownSim>
      <!--
        <gazebo_joint_control_pid>
          <p>0.1</p>
          <i>0</i>
          <d>0</d>
          <iMax>0</iMax>
          <iMin>0</iMin>
          <cmdMax>3</cmdMax>
          <cmdMin>-3</cmdMin>
        </gazebo_joint_control_pid>
      -->
    </plugin>
  </gazebo>
  <gazebo reference="rotor_0">
    <material>Gazebo/Red</material>
  </gazebo>
  <joint name="rotor_1_joint" type="continuous">
    <origin rpy="0 0 0" xyz="-0.175 0.175 0.035"/>
    <axis xyz="0 0 1"/>
    <!-- TODO(ff): not currently set because it's not yet supported -->
    <!-- <limit effort="2000" velocity="${max_rot_velocity}" /> -->
    <parent link="arm_2"/>
    <child link="rotor_1"/>
  </joint>
  <!-- TODO(ff): not currently set because it's not yet supported -->
  <!-- <gazebo reference="rotor_${motor_number}_joint"> <axis> <xyz>0 0 1</xyz>
      <limit> <velocity> ${max_rot_velocity} </velocity> </limit> </axis> </gazebo> -->
  <link name="rotor_1">
    <inertial>
      <mass value="0.001"/>
      <!-- [kg] -->
      <inertia ixx="1.95e-06" ixy="0.0" ixz="0.0" iyy="0.0005462083333333332" iyz="0.0" izz="0.0005480083333333334"/>
    </inertial>
    <visual>
      <geometry>
        <!-- <cylinder length="0.005" radius="${radius_rotor}"/> -->
        <!-- [m] -->
        <!-- <mesh filename="package://mav_description/meshes/propeller_${direction}.dae" -->
        <mesh filename="package://mav_description/meshes/ndt2/prop.stl_ccw.dae" scale="1 1 1"/>
        <!-- <box size="${2*radius_rotor} 0.01 0.005"/> -->
      </geometry>
    </visual>
    <collision>
      <geometry>
        <cylinder length="0.005" radius="0.128"/>
        <!-- [m] -->
      </geometry>
    </collision>
  </link>
  <gazebo>
    <plugin filename="librotors_gazebo_motor_model.so" name="rear_left_motor_model">
      <robotNamespace>ndt2</robotNamespace>
      <jointName>rotor_1_joint</jointName>
      <linkName>rotor_1</linkName>
      <turningDirection>ccw</turningDirection>
      <timeConstantUp>0.0125</timeConstantUp>
      <timeConstantDown>0.025</timeConstantDown>
      <maxRotVelocity>1100</maxRotVelocity>
      <motorConstant>8.54858e-05</motorConstant>
      <momentConstant>0.06</momentConstant>
      <commandSubTopic>/gazebo/command/motor_speed</commandSubTopic>
      <motorNumber>1</motorNumber>
      <rotorDragCoefficient>0.000175</rotorDragCoefficient>
      <rollingMomentCoefficient>1e-06</rollingMomentCoefficient>
      <motorSpeedPubTopic>/motor_speed/1</motorSpeedPubTopic>
      <rotorVelocitySlowdownSim>100</rotorVelocitySlowdownSim>
      <!--
        <gazebo_joint_control_pid>
          <p>0.1</p>
          <i>0</i>
          <d>0</d>
          <iMax>0</iMax>
          <iMin>0</iMin>
          <cmdMax>3</cmdMax>
          <cmdMin>-3</cmdMin>
        </gazebo_joint_control_pid>
      -->
    </plugin>
  </gazebo>
  <gazebo reference="rotor_1">
    <material>Gazebo/Blue</material>
  </gazebo>
  <joint name="rotor_2_joint" type="continuous">
    <origin rpy="0 0 0" xyz="-0.175 -0.175 0.035"/>
    <axis xyz="0 0 1"/>
    <!-- TODO(ff): not currently set because it's not yet supported -->
    <!-- <limit effort="2000" velocity="${max_rot_velocity}" /> -->
    <parent link="arm_1"/>
    <child link="rotor_2"/>
  </joint>
  <!-- TODO(ff): not currently set because it's not yet supported -->
  <!-- <gazebo reference="rotor_${motor_number}_joint"> <axis> <xyz>0 0 1</xyz>
      <limit> <velocity> ${max_rot_velocity} </velocity> </limit> </axis> </gazebo> -->
  <link name="rotor_2">
    <inertial>
      <mass value="0.001"/>
      <!-- [kg] -->
      <inertia ixx="1.95e-06" ixy="0.0" ixz="0.0" iyy="0.0005462083333333332" iyz="0.0" izz="0.0005480083333333334"/>
    </inertial>
    <visual>
      <geometry>
        <!-- <cylinder length="0.005" radius="${radius_rotor}"/> -->
        <!-- [m] -->
        <!-- <mesh filename="package://mav_description/meshes/propeller_${direction}.dae" -->
        <mesh filename="package://mav_description/meshes/ndt2/prop.stl_cw.dae" scale="1 1 1"/>
        <!-- <box size="${2*radius_rotor} 0.01 0.005"/> -->
      </geometry>
    </visual>
    <collision>
      <geometry>
        <cylinder length="0.005" radius="0.128"/>
        <!-- [m] -->
      </geometry>
    </collision>
  </link>
  <gazebo>
    <plugin filename="librotors_gazebo_motor_model.so" name="front_left_motor_model">
      <robotNamespace>ndt2</robotNamespace>
      <jointName>rotor_2_joint</jointName>
      <linkName>rotor_2</linkName>
      <turningDirection>cw</turningDirection>
      <timeConstantUp>0.0125</timeConstantUp>
      <timeConstantDown>0.025</timeConstantDown>
      <maxRotVelocity>1100</maxRotVelocity>
      <motorConstant>8.54858e-05</motorConstant>
      <momentConstant>0.06</momentConstant>
      <commandSubTopic>/gazebo/command/motor_speed</commandSubTopic>
      <motorNumber>2</motorNumber>
      <rotorDragCoefficient>0.000175</rotorDragCoefficient>
      <rollingMomentCoefficient>1e-06</rollingMomentCoefficient>
      <motorSpeedPubTopic>/motor_speed/2</motorSpeedPubTopic>
      <rotorVelocitySlowdownSim>100</rotorVelocitySlowdownSim>
      <!--
        <gazebo_joint_control_pid>
          <p>0.1</p>
          <i>0</i>
          <d>0</d>
          <iMax>0</iMax>
          <iMin>0</iMin>
          <cmdMax>3</cmdMax>
          <cmdMin>-3</cmdMin>
        </gazebo_joint_control_pid>
      -->
    </plugin>
  </gazebo>
  <gazebo reference="rotor_2">
    <material>Gazebo/Red</material>
  </gazebo>
  <joint name="rotor_3_joint" type="continuous">
    <origin rpy="0 0 0" xyz="0.175 0.175 0.035"/>
    <axis xyz="0 0 1"/>
    <!-- TODO(ff): not currently set because it's not yet supported -->
    <!-- <limit effort="2000" velocity="${max_rot_velocity}" /> -->
    <parent link="arm_3"/>
    <child link="rotor_3"/>
  </joint>
  <!-- TODO(ff): not currently set because it's not yet supported -->
  <!-- <gazebo reference="rotor_${motor_number}_joint"> <axis> <xyz>0 0 1</xyz>
      <limit> <velocity> ${max_rot_velocity} </velocity> </limit> </axis> </gazebo> -->
  <link name="rotor_3">
    <inertial>
      <mass value="0.001"/>
      <!-- [kg] -->
      <inertia ixx="1.95e-06" ixy="0.0" ixz="0.0" iyy="0.0005462083333333332" iyz="0.0" izz="0.0005480083333333334"/>
    </inertial>
    <visual>
      <geometry>
        <!-- <cylinder length="0.005" radius="${radius_rotor}"/> -->
        <!-- [m] -->
        <!-- <mesh filename="package://mav_description/meshes/propeller_${direction}.dae" -->
        <mesh filename="package://mav_description/meshes/ndt2/prop.stl_cw.dae" scale="1 1 1"/>
        <!-- <box size="${2*radius_rotor} 0.01 0.005"/> -->
      </geometry>
    </visual>
    <collision>
      <geometry>
        <cylinder length="0.005" radius="0.128"/>
        <!-- [m] -->
      </geometry>
    </collision>
  </link>
  <gazebo>
    <plugin filename="librotors_gazebo_motor_model.so" name="rear_right_motor_model">
      <robotNamespace>ndt2</robotNamespace>
      <jointName>rotor_3_joint</jointName>
      <linkName>rotor_3</linkName>
      <turningDirection>cw</turningDirection>
      <timeConstantUp>0.0125</timeConstantUp>
      <timeConstantDown>0.025</timeConstantDown>
      <maxRotVelocity>1100</maxRotVelocity>
      <motorConstant>8.54858e-05</motorConstant>
      <momentConstant>0.06</momentConstant>
      <commandSubTopic>/gazebo/command/motor_speed</commandSubTopic>
      <motorNumber>3</motorNumber>
      <rotorDragCoefficient>0.000175</rotorDragCoefficient>
      <rollingMomentCoefficient>1e-06</rollingMomentCoefficient>
      <motorSpeedPubTopic>/motor_speed/3</motorSpeedPubTopic>
      <rotorVelocitySlowdownSim>100</rotorVelocitySlowdownSim>
      <!--
        <gazebo_joint_control_pid>
          <p>0.1</p>
          <i>0</i>
          <d>0</d>
          <iMax>0</iMax>
          <iMin>0</iMin>
          <cmdMax>3</cmdMax>
          <cmdMin>-3</cmdMin>
        </gazebo_joint_control_pid>
      -->
    </plugin>
  </gazebo>
  <gazebo reference="rotor_3">
    <material>Gazebo/Blue</material>
  </gazebo>
  <material name="silver">
    <color rgba="0.700 0.700 0.700 1.000"/>
  </material>
  <transmission name="Rev3_tran">
    <type>transmission_interface/SimpleTransmission</type>
    <joint name="Rev3">
      <hardwareInterface>hardware_interface/PositionJointInterface</hardwareInterface>
    </joint>
    <actuator name="Rev3_actr">
      <hardwareInterface>hardware_interface/PositionJointInterface</hardwareInterface>
      <mechanicalReduction>1</mechanicalReduction>
    </actuator>
  </transmission>
  <transmission name="Rev4_tran">
    <type>transmission_interface/SimpleTransmission</type>
    <joint name="Rev4">
      <hardwareInterface>hardware_interface/PositionJointInterface</hardwareInterface>
    </joint>
    <actuator name="Rev4_actr">
      <hardwareInterface>hardware_interface/PositionJointInterface</hardwareInterface>
      <mechanicalReduction>1</mechanicalReduction>
    </actuator>
  </transmission>
  <transmission name="Rev5_tran">
    <type>transmission_interface/SimpleTransmission</type>
    <joint name="Rev5">
      <hardwareInterface>hardware_interface/PositionJointInterface</hardwareInterface>
    </joint>
    <actuator name="Rev5_actr">
      <hardwareInterface>hardware_interface/PositionJointInterface</hardwareInterface>
      <mechanicalReduction>1</mechanicalReduction>
    </actuator>
  </transmission>
  <transmission name="Rev6_tran">
    <type>transmission_interface/SimpleTransmission</type>
    <joint name="Rev6">
      <hardwareInterface>hardware_interface/PositionJointInterface</hardwareInterface>
    </joint>
    <actuator name="Rev6_actr">
      <hardwareInterface>hardware_interface/PositionJointInterface</hardwareInterface>
      <mechanicalReduction>1</mechanicalReduction>
    </actuator>
  </transmission>
  <transmission name="Rev7_tran">
    <type>transmission_interface/SimpleTransmission</type>
    <joint name="Rev7">
      <hardwareInterface>hardware_interface/PositionJointInterface</hardwareInterface>
    </joint>
    <actuator name="Rev7_actr">
      <hardwareInterface>hardware_interface/PositionJointInterface</hardwareInterface>
      <mechanicalReduction>1</mechanicalReduction>
    </actuator>
  </transmission>
  <transmission name="Rev8_tran">
    <type>transmission_interface/SimpleTransmission</type>
    <joint name="Rev8">
      <hardwareInterface>hardware_interface/PositionJointInterface</hardwareInterface>
    </joint>
    <actuator name="Rev8_actr">
      <hardwareInterface>hardware_interface/PositionJointInterface</hardwareInterface>
      <mechanicalReduction>1</mechanicalReduction>
    </actuator>
  </transmission>
  <gazebo reference="base_link">
    <material>Gazebo/Silver</material>
    <mu1>0.2</mu1>
    <mu2>0.2</mu2>
    <selfCollide>true</selfCollide>
    <gravity>true</gravity>
  </gazebo>
  <gazebo reference="shoulder_2_1">
    <material>Gazebo/Silver</material>
    <mu1>0.2</mu1>
    <mu2>0.2</mu2>
    <selfCollide>true</selfCollide>
  </gazebo>
  <gazebo reference="first_Link_200_1">
    <material>Gazebo/Silver</material>
    <mu1>0.2</mu1>
    <mu2>0.2</mu2>
    <selfCollide>true</selfCollide>
  </gazebo>
  <gazebo reference="second_Link_200__1__1">
    <material>Gazebo/Silver</material>
    <mu1>0.2</mu1>
    <mu2>0.2</mu2>
    <selfCollide>true</selfCollide>
  </gazebo>
  <gazebo reference="Yaw_1">
    <material>Gazebo/Silver</material>
    <mu1>0.2</mu1>
    <mu2>0.2</mu2>
    <selfCollide>true</selfCollide>
  </gazebo>
  <gazebo reference="Pitch_1">
    <material>Gazebo/Silver</material>
    <mu1>0.2</mu1>
    <mu2>0.2</mu2>
    <selfCollide>true</selfCollide>
  </gazebo>
  <gazebo reference="Roll_1">
    <material>Gazebo/Silver</material>
    <mu1>0.2</mu1>
    <mu2>0.2</mu2>
    <selfCollide>true</selfCollide>
  </gazebo>
  <joint name="orientation_joint" type="fixed">
    <parent link="base_link"/>
    <child link="orientation_link"/>
    <origin rpy="1.5707963267948966 0 -1.5707963267948966" xyz="0 0 0.0"/>
  </joint>
  <link name="orientation_link"/>
  <joint name="base_arm_joint" type="fixed">
    <parent link="orientation_link"/>
    <child link="arm_base_link"/>
    <origin rpy="0 0 0" xyz="0.011623 -0.033576 -0.423212"/>
  </joint>
  <link name="arm_base_link">
    <inertial>
      <origin rpy="0 0 0" xyz="-0.011622835562823751 0.026076416772968965 0.4232115499965129"/>
      <mass value="0.6539245694270445"/>
      <inertia ixx="0.00013" ixy="0.0" ixz="0.0" iyy="0.000235" iyz="-0.0" izz="0.00013"/>
    </inertial>
    <visual>
      <origin rpy="0 0 0" xyz="0 0 0"/>
      <geometry>
        <mesh filename="package://arm_description/meshes/base_link.stl" scale="0.001 0.001 0.001"/>
      </geometry>
      <material name="silver"/>
    </visual>
    <collision>
      <origin rpy="0 0 0" xyz="0 0 0"/>
      <geometry>
        <mesh filename="package://arm_description/meshes/base_link.stl" scale="0.001 0.001 0.001"/>
      </geometry>
    </collision>
  </link>
  <link name="shoulder_2_1">
    <inertial>
      <origin rpy="0 0 0" xyz="-7.295146686063514e-06 -0.03272366123986107 8.378471211212268e-06"/>
      <mass value="0.18907008597028982"/>
      <inertia ixx="8.7e-05" ixy="0.0" ixz="0.0" iyy="8.1e-05" iyz="-0.0" izz="6.5e-05"/>
    </inertial>
    <visual>
      <origin rpy="0 0 0" xyz="0.011623 -0.033576 -0.423212"/>
      <geometry>
        <mesh filename="package://arm_description/meshes/shoulder_2_1.stl" scale="0.001 0.001 0.001"/>
      </geometry>
      <material name="silver"/>
    </visual>
    <collision>
      <origin rpy="0 0 0" xyz="0.011623 -0.033576 -0.423212"/>
      <geometry>
        <mesh filename="package://arm_description/meshes/shoulder_2_1.stl" scale="0.001 0.001 0.001"/>
      </geometry>
    </collision>
  </link>
  <gazebo reference="shoulder_2_1">
    <kp>1000000.0</kp>
    <kd>1000.0</kd>
    <mu1>0.8</mu1>
    <mu2>0.8</mu2>
    <maxVel>0.0</maxVel>
    <minDepth>0.001</minDepth>
  </gazebo>
  <link name="first_Link_200_1">
    <inertial>
      <origin rpy="0 0 0" xyz="0.01000015992057332 4.0839001024493837e-07 -0.10000041458331238"/>
      <mass value="0.04111040389630535"/>
      <inertia ixx="0.000248" ixy="-0.0" ixz="-0.0" iyy="0.000248" iyz="0.0" izz="3e-06"/>
    </inertial>
    <visual>
      <origin rpy="0 0 0" xyz="0.021623 0.001424 -0.423212"/>
      <geometry>
        <mesh filename="package://arm_description/meshes/first_Link_200_1.stl" scale="0.001 0.001 0.001"/>
      </geometry>
      <material name="silver"/>
    </visual>
    <collision>
      <origin rpy="0 0 0" xyz="0.021623 0.001424 -0.423212"/>
      <geometry>
        <mesh filename="package://arm_description/meshes/first_Link_200_1.stl" scale="0.001 0.001 0.001"/>
      </geometry>
    </collision>
  </link>
  <link name="second_Link_200__1__1">
    <inertial>
      <origin rpy="0 0 0" xyz="0.010000158743883165 4.123575158946919e-07 -0.07070574631913057"/>
      <mass value="0.031775151367082886"/>
      <inertia ixx="0.000128" ixy="-0.0" ixz="0.0" iyy="0.000128" iyz="0.0" izz="2e-06"/>
    </inertial>
    <visual>
      <origin rpy="0 0 0" xyz="0.041623 0.001424 -0.223212"/>
      <geometry>
        <mesh filename="package://arm_description/meshes/second_Link_200__1__1.stl" scale="0.001 0.001 0.001"/>
      </geometry>
      <material name="silver"/>
    </visual>
    <collision>
      <origin rpy="0 0 0" xyz="0.041623 0.001424 -0.223212"/>
      <geometry>
        <mesh filename="package://arm_description/meshes/second_Link_200__1__1.stl" scale="0.001 0.001 0.001"/>
      </geometry>
    </collision>
  </link>
  <link name="Yaw_1">
    <inertial>
      <origin rpy="0 0 0" xyz="1.6443717608394248e-07 4.10947984520911e-07 -0.009712908448932418"/>
      <mass value="0.019335321488620901"/>
      <inertia ixx="0.0" ixy="0.0" ixz="0.0" iyy="1e-06" iyz="0.0" izz="1e-06"/>
    </inertial>
    <visual>
      <origin rpy="0 0 0" xyz="0.031623 0.001424 -0.033212"/>
      <geometry>
        <mesh filename="package://arm_description/meshes/Yaw_1.stl" scale="0.001 0.001 0.001"/>
      </geometry>
      <material name="silver"/>
    </visual>
    <collision>
      <origin rpy="0 0 0" xyz="0.031623 0.001424 -0.033212"/>
      <geometry>
        <mesh filename="package://arm_description/meshes/Yaw_1.stl" scale="0.001 0.001 0.001"/>
      </geometry>
    </collision>
  </link>
  <link name="Pitch_1">
    <inertial>
      <origin rpy="0 0 0" xyz="0.012000164437172327 4.1677296895841626e-07 -0.00730630929765641"/>
      <mass value="0.017370138299177099"/>
      <inertia ixx="1e-06" ixy="0.0" ixz="-0.0" iyy="1e-06" iyz="-0.0" izz="1e-06"/>
    </inertial>
    <visual>
      <origin rpy="0 0 0" xyz="0.043623 0.001424 -0.023212"/>
      <geometry>
        <mesh filename="package://arm_description/meshes/Pitch_1.stl" scale="0.001 0.001 0.001"/>
      </geometry>
      <material name="silver"/>
    </visual>
    <collision>
      <origin rpy="0 0 0" xyz="0.043623 0.001424 -0.023212"/>
      <geometry>
        <mesh filename="package://arm_description/meshes/Pitch_1.stl" scale="0.001 0.001 0.001"/>
      </geometry>
    </collision>
  </link>
  <link name="Roll_1">
    <inertial>
      <origin rpy="0 0 0" xyz="1.6443717608394248e-07 4.1677296895668153e-07 0.007499957912210709"/>
      <mass value="0.016738716241950105"/>
      <inertia ixx="1e-06" ixy="0.0" ixz="-0.0" iyy="1e-06" iyz="-0.0" izz="1e-06"/>
    </inertial>
    <visual>
      <origin rpy="0 0 0" xyz="0.031623 0.001424 0.00881"/>
      <geometry>
        <mesh filename="package://arm_description/meshes/Roll_1.stl" scale="0.001 0.001 0.001"/>
      </geometry>
      <material name="silver"/>
    </visual>
    <collision>
      <origin rpy="0 0 0" xyz="0.031623 0.001424 0.00881"/>
      <geometry>
        <mesh filename="package://arm_description/meshes/Roll_1.stl" scale="0.001 0.001 0.001"/>
      </geometry>
    </collision>
  </link>
  <joint name="Rev3" type="revolute">
    <origin rpy="0 0 0" xyz="-0.011623 0.033576 0.423212"/>
    <parent link="arm_base_link"/>
    <child link="shoulder_2_1"/>
    <axis xyz="0.0 1.0 -0.0"/>
    <limit effort="5" lower="-3.1415" upper="3.1415" velocity="1.57"/>
  </joint>
  <joint name="Rev4" type="revolute">
    <origin rpy="0 0 0" xyz="-0.01 -0.035 0.0"/>
    <parent link="shoulder_2_1"/>
    <child link="first_Link_200_1"/>
    <axis xyz="1.0 0.0 0.0"/>
    <limit effort="5" lower="-3.1415" upper="3.1415" velocity="1.57"/>
  </joint>
  <joint name="Rev5" type="revolute">
    <origin rpy="0 0 0" xyz="-0.02 0.0 -0.2"/>
    <parent link="first_Link_200_1"/>
    <child link="second_Link_200__1__1"/>
    <axis xyz="1.0 0.0 0.0"/>
    <limit effort="5" lower="-3.1415" upper="3.1415" velocity="1.57"/>
  </joint>
  <joint name="Rev6" type="revolute">
    <origin rpy="0 0 0" xyz="0.01 0.0 -0.19"/>
    <parent link="second_Link_200__1__1"/>
    <child link="Yaw_1"/>
    <axis xyz="0.0 0.0 1.0"/>
    <limit effort="5" lower="-3.1415" upper="3.1415" velocity="1.57"/>
  </joint>
  <joint name="Rev7" type="revolute">
    <origin rpy="0 0 0" xyz="-0.012 0.0 -0.01"/>
    <parent link="Yaw_1"/>
    <child link="Pitch_1"/>
    <axis xyz="1.0 -0.0 0.0"/>
    <limit effort="5" lower="-3.1415" upper="3.1415" velocity="1.57"/>
  </joint>
  <joint name="Rev8" type="revolute">
    <origin rpy="0 0 0" xyz="0.012 0.0 -0.032022"/>
    <parent link="Pitch_1"/>
    <child link="Roll_1"/>
    <axis xyz="-0.0 -0.0 -1.0"/>
    <limit effort="5" lower="-3.1415" upper="3.1415" velocity="1.57"/>
  </joint>
  <!-- CAMERA SENSOR -->
  <link name="camera_link">
    <inertial>
      <origin rpy="0 0 0" xyz="0 0 0"/>
      <mass value="0.1"/>
      <inertia ixx="0.0009933333333333335" ixy="0.0" ixz="0.0" iyy="0.0009933333333333335" iyz="0.0" izz="0.001926666666666667"/>
    </inertial>
    <visual>
      <origin rpy="0 0 0" xyz="0.0 0.0 0"/>
      <geometry>
        <box size="0.02 0.02 0.02"/>
      </geometry>
      <material name="red">
        <color rgba="0.8 0.0 0.0 1.0"/>
      </material>
    </visual>
    <collision>
      <origin rpy="0 0 0" xyz="0.0 0.0 0"/>
    </collision>
  </link>
  <joint name="camera_joint" type="fixed">
    <origin rpy="0 0 0.0" xyz="0.085 0.0 0.01"/>
    <parent link="base_link"/>
    <child link="camera_link"/>
  </joint>
  <gazebo reference="camera_link">
    <sensor name="camera1" type="camera">
      <update_rate>30.0</update_rate>
      <camera name="head">
        <horizontal_fov>1.3962634</horizontal_fov>
        <image>
          <width>800</width>
          <height>600</height>
          <format>R8G8B8</format>
        </image>
        <clip>
          <near>0.02</near>
          <far>300</far>
        </clip>
        <noise>
          <type>gaussian</type>
          <mean>0.0</mean>
          <stddev>0.007</stddev>
        </noise>
      </camera>
      <plugin filename="libgazebo_ros_camera.so" name="camera_controller">
        <alwaysOn>true</alwaysOn>
        <updateRate>0.0</updateRate>
        <cameraName>/camera</cameraName>
        <imageTopicName>image_raw</imageTopicName>
        <cameraInfoTopicName>camera_info</cameraInfoTopicName>
        <frameName>camera_link</frameName>
        <hackBaseline>0.07</hackBaseline>
        <distortionK1>0.0</distortionK1>
        <distortionK2>0.0</distortionK2>
        <distortionK3>0.0</distortionK3>
        <distortionT1>0.0</distortionT1>
        <distortionT2>0.0</distortionT2>
      </plugin>
    </sensor>
  </gazebo>
</robot>

